/*
 * Copyright (c) 2019-2020 by The Monix Project Developers.
 * See the project homepage at: https://monix.io
 *
 * Licensed under the Apache License, Version 2.0 (the "License");
 * you may not use this file except in compliance with the License.
 * You may obtain a copy of the License at
 *
 *     http://www.apache.org/licenses/LICENSE-2.0
 *
 * Unless required by applicable law or agreed to in writing, software
 * distributed under the License is distributed on an "AS IS" BASIS,
 * WITHOUT WARRANTIES OR CONDITIONS OF ANY KIND, either express or implied.
 * See the License for the specific language governing permissions and
 * limitations under the License.
 */

package monix.bio

import monix.execution.exceptions.DummyException
import monix.execution.internal.Platform

import scala.concurrent.TimeoutException
import scala.concurrent.duration._
import scala.util.{Failure, Success}

object TaskErrorSuite extends BaseTestSuite {
  test("IO.attempt should expose typed error") { implicit s =>
    val dummy = "dummy"
    val r = IO.raiseError(dummy).attempt.runSyncStep
    assertEquals(r, Right(Left(dummy)))
  }

  test("IO.attempt should not expose unexpected error") { implicit s =>
    val dummy = DummyException("dummy")
    val f = IO.terminate(dummy).attempt.runToFuture
    assertEquals(f.value, Some(Failure(dummy)))
  }

  test("IO.attempt should work for successful values") { implicit s =>
    val r = IO.now(10).attempt.runSyncStep
    assertEquals(r, Right(Right(10)))
  }

  test("IO.rethrow should turn Left to typed error") { implicit s =>
    val dummy = "dummy"
    val f = IO.now(Left(dummy)).rethrow.attempt.runToFuture
    assertEquals(f.value, Some(Success(Left(dummy))))
  }

  test("IO.rethrow should turn Right to success value") { implicit s =>
    val dummy = "dummy"
    val r = IO.now(Right(dummy)).rethrow.runSyncStep
    assertEquals(r, Right(dummy))
  }

  test("IO.failed should expose typed error") { implicit s =>
    val dummy = "dummy"
    val r = IO.raiseError(dummy).failed.runSyncStep
    assertEquals(r, Right(dummy))
  }

  test("IO.failed should fail for unexpected error") { implicit s =>
    val dummy = DummyException("dummy")

    intercept[DummyException] {
      IO.terminate(dummy).failed.runSyncStep
    }
    ()
  }

  test("IO.failed should fail for successful values") { implicit s =>
    intercept[NoSuchElementException] {
      IO.now(10).failed.runSyncStep
    }
    ()
  }

  test("IO#onErrorRecover should mirror source on success") { implicit s =>
    val task = (UIO.evalAsync(1): IO[String, Int]).onErrorRecover { case _: String => 99 }
    val f = task.attempt.runToFuture
    s.tick()
    assertEquals(f.value, Some(Success(Right(1))))
  }

  test("IO#onErrorRecover should recover typed error") { implicit s =>
    val ex = "dummy"
    val task = (IO.raiseError(ex): IO[String, Int]).onErrorRecover { case "dummy" =>
      99
    }

    val f = task.attempt.runToFuture
    s.tick()
    assertEquals(f.value, Some(Success(Right(99))))
  }

  test("IO#onErrorRecover should not recover unexpected error") { implicit s =>
    val ex = DummyException("dummy")
    val task = (IO.terminate(ex): IO[String, Int]).onErrorRecover { case _ =>
      99
    }

    val f = task.attempt.runToFuture
    s.tick()
    assertEquals(f.value, Some(Failure(ex)))
  }

  test("IO#onErrorRecover should protect against user code") { implicit s =>
    val ex1 = DummyException("one")
    val ex2 = DummyException("two")

    val task = IO[Int](if (1 == 1) throw ex1 else 1).onErrorRecover { case _ => throw ex2 }

    val f = task.runToFuture; s.tick()
    assertEquals(f.value, Some(Failure(ex2)))
  }

  test("IO#onErrorHandle should mirror source on success") { implicit s =>
    val task = (UIO.evalAsync(1): IO[String, Int]).onErrorHandle { _: String =>
      99
    }
    val f = task.runToFuture
    s.tick()
    assertEquals(f.value, Some(Success(1)))
  }

  test("IO#onErrorHandle should recover typed error") { implicit s =>
    val ex = "dummy"
    val task = (IO.raiseError(ex): IO[String, Int]).onErrorHandle { _: String =>
      99
    }

    val f = task.runToFuture
    s.tick()
    assertEquals(f.value, Some(Success(99)))
  }

  test("IO#onErrorHandle should not recover unexpected error") { implicit s =>
    val ex = DummyException("dummy")
    val task = IO.evalTotal[Int](if (1 == 1) throw ex else 1).onErrorHandle { _ =>
      99
    }

    val f = task.runToFuture
    s.tick()
    assertEquals(f.value, Some(Failure(ex)))
  }

  test("IO#onErrorHandle should protect against user code") { implicit s =>
    val ex1 = "one"
    val ex2 = DummyException("two")

    val task = (IO.raiseError(ex1): IO[String, Int]).onErrorHandle { _ =>
      throw ex2
    }

    val f = task.runToFuture; s.tick()
    assertEquals(f.value, Some(Failure(ex2)))
  }

  test("IO.onErrorFallbackTo should mirror source onSuccess") { implicit s =>
    val task = UIO.evalAsync(1).onErrorFallbackTo(UIO.evalAsync(2))
    val f = task.runToFuture
    s.tick()
    assertEquals(f.value, Some(Success(1)))
  }

  test("IO.onErrorFallbackTo should fallback to backup onError") { implicit s =>
    val ex = "dummy"
    val task = (IO.raiseError(ex): IO[String, Int]).onErrorFallbackTo(UIO.evalAsync(2))
    val f = task.runToFuture
    s.tick()
    assertEquals(f.value, Some(Success(2)))
  }

  test("IO.onErrorFallbackTo should not fallback to backup onTermination") { implicit s =>
    val ex = DummyException("dummy")
    val task = (IO.terminate(ex): IO[String, Int]).onErrorFallbackTo(UIO.evalAsync(2))
    val f = task.runToFuture
    s.tick()
    assertEquals(f.value, Some(Failure(ex)))
  }

  test("IO.onErrorFallbackTo should protect against user code") { implicit s =>
    val ex = "dummy"
    val err = DummyException("unexpected")
    val task = (IO.raiseError(ex): IO[String, Int]).executeAsync.onErrorFallbackTo(IO.defer(throw err))
    val f = task.attempt.runToFuture
    s.tick()
    assertEquals(f.value, Some(Success(Left(err))))
  }

  test("IO.onErrorFallbackTo should be cancelable if the ExecutionModel allows it") { implicit s =>
    def recursive(): UIO[Int] = {
      IO.raiseError("dummy").onErrorFallbackTo(IO.deferTotal(recursive()))
    }

    val task = recursive().executeWithOptions(_.enableAutoCancelableRunLoops)
    val f = task.runToFuture
    assertEquals(f.value, None)

    // cancelling after scheduled for execution, but before execution
    f.cancel(); s.tick()
    assertEquals(f.value, None)
  }

  test("IO.onErrorRestart should mirror the source onSuccess") { implicit s =>
    var tries = 0
    val task = UIO.eval { tries += 1; 1 }.onErrorRestart(10)
    val f = task.runToFuture

    assertEquals(f.value, Some(Success(1)))
    assertEquals(tries, 1)
  }

  test("IO.onErrorRestart should retry onError") { implicit s =>
    val ex = "dummy"
    var tries = 0
    val task = IO.deferTotal { tries += 1; if (tries < 5) IO.raiseError(ex) else IO.now(1) }.onErrorRestart(10)
    val f = task.attempt.runToFuture

    assertEquals(f.value, Some(Success(Right(1))))
    assertEquals(tries, 5)
  }

  test("IO.onErrorRestart should emit onError after max retries") { implicit s =>
    val ex = DummyException("dummy")
    var tries = 0
    val task = IO.eval { tries += 1; throw ex }.onErrorRestart(10)
    val f = task.attempt.runToFuture

    assertEquals(f.value, Some(Success(Left(ex))))
    assertEquals(tries, 11)
  }

  test("IO.onErrorRestart should be cancelable if ExecutionModel permits") { implicit s =>
    val batchSize = (s.executionModel.recommendedBatchSize * 2).toLong
    val task = IO[Int](throw DummyException("dummy"))
      .onErrorRestart(batchSize)

    val f = task.executeWithOptions(_.enableAutoCancelableRunLoops).runToFuture
    assertEquals(f.value, None)

    // cancelling after scheduled for execution, but before execution
    f.cancel(); s.tick()
    assertEquals(f.value, None)
  }

  test("IO.onErrorRestart should not restart on terminate error") { implicit s =>
    var tries = 0
    val ex = DummyException("dummy")
    val task = IO.eval { tries += 1; throw ex }.hideErrors.onErrorRestart(5)
    val f = task.runToFuture

    assertEquals(f.value, Some(Failure(ex)))
    assertEquals(tries, 1)
  }

  test("IO.onErrorRestartIf should mirror the source onSuccess") { implicit s =>
    var tries = 0
    val task = IO.eval { tries += 1; 1 }.onErrorRestartIf(_ => tries < 10)
    val f = task.runToFuture

    assertEquals(f.value, Some(Success(1)))
    assertEquals(tries, 1)
  }

  test("IO.onErrorRestartIf should retry onError") { implicit s =>
    val ex = DummyException("dummy")
    var tries = 0
    val task = IO.eval { tries += 1; if (tries < 5) throw ex else 1 }
      .onErrorRestartIf(_ => tries <= 10)

    val f = task.runToFuture
    assertEquals(f.value, Some(Success(1)))
    assertEquals(tries, 5)
  }

  test("IO.onErrorRestartIf should emit onError") { implicit s =>
    val ex = DummyException("dummy")
    var tries = 0
    val task = IO.eval { tries += 1; throw ex }
      .onErrorRestartIf(_ => tries <= 10)

    val f = task.runToFuture
    assertEquals(f.value, Some(Failure(ex)))
    assertEquals(tries, 11)
  }

  test("IO.onErrorRestartIf should be cancelable if ExecutionModel permits") { implicit s =>
    val task = IO[Int](throw DummyException("dummy")).onErrorRestartIf(_ => true)
    val f = task.executeWithOptions(_.enableAutoCancelableRunLoops).runToFuture
    assertEquals(f.value, None)

    // cancelling after scheduled for execution, but before execution
    f.cancel(); s.tick()
    assertEquals(f.value, None)
  }

  test("IO.onErrorRestartIf should not restart on terminate error") { implicit s =>
    var tries = 0
    val ex = DummyException("dummy")
    val task: UIO[Int] = IO.eval { tries += 1; throw ex }.hideErrors
    val f = task.onErrorRestartIf(_ => tries < 5).runToFuture

    assertEquals(f.value, Some(Failure(ex)))
    assertEquals(tries, 1)
  }

  test("IO.onErrorRestartIf should restart on typed error") { implicit s =>
    var tries = 0
    val task = IO.unit.flatMap { _ =>
      tries += 1; if (tries < 5) IO.raiseError("error") else IO.pure(1)
    }
    val f = task.onErrorRestartIf(_ == "error").attempt.runToFuture
    assertEquals(f.value, Some(Success(Right(1))))
    assertEquals(tries, 5)
  }

  test("IO#onErrorRecoverWith should mirror source on success") { implicit s =>
    val task = (UIO.evalAsync(1): IO[Int, Int]).onErrorRecoverWith { case _: Int => UIO.evalAsync(99) }
    val f = task.attempt.runToFuture
    s.tick()
    assertEquals(f.value, Some(Success(Right(1))))
  }

  test("IO#onErrorRecoverWith should recover") { implicit s =>
    val ex = DummyException("dummy")
    val task = IO[Int](throw ex).onErrorRecoverWith { case _: DummyException =>
      IO.evalAsync(99)
    }

    val f = task.runToFuture
    s.tick()
    assertEquals(f.value, Some(Success(99)))
  }

  test("IO#mapErrorPartial should handle recoverable exceptions") { implicit s =>
    val ex = DummyException("dummy")
    val io: IO[String, Int] = IO(throw ex).mapErrorPartial { case e: DummyException =>
      e.message
    }

    val f = io.attempt.runToFuture
    s.tick()
    assertEquals(f.value, Some(Success(Left("dummy"))))
  }

  test("IO#mapErrorPartial should terminate on non-recoverable exceptions") { implicit s =>
    val ex = DummyException("dummy")
    val io: IO[String, Int] = IO(throw ex).mapErrorPartial { case e: IllegalArgumentException =>
      "not found"
    }

    val f = io.attempt.runToFuture
    s.tick()
    assertEquals(f.value, Some(Failure(ex)))
  }

  test("IO#mapErrorPartialWith should handle recoverable exceptions") { implicit s =>
    val ex = DummyException("dummy")
    val io: IO[String, Int] = IO(throw ex).mapErrorPartialWith { case e: DummyException =>
      IO.raiseError(e.message)
    }

    val f = io.attempt.runToFuture
    s.tick()
    assertEquals(f.value, Some(Success(Left("dummy"))))
  }

  test("IO#mapErrorPartialWith should terminate on non-recoverable exceptions") { implicit s =>
    val ex = DummyException("dummy")
    val io: IO[String, Int] = IO(throw ex).mapErrorPartialWith { case e: IllegalArgumentException =>
      IO.raiseError("not found")
    }

    val f = io.attempt.runToFuture
    s.tick()
    assertEquals(f.value, Some(Failure(ex)))
  }

  test("IO#onErrorRecoverWith should protect against user code") { implicit s =>
    val ex1 = DummyException("one")
    val ex2 = DummyException("two")

    val task = IO[Int](throw ex1).onErrorRecoverWith { case _ => throw ex2 }

    val f = task.runToFuture; s.tick()
    assertEquals(f.value, Some(Failure(ex2)))
  }

  test("IO#onErrorRecoverWith has a cancelable fallback") { implicit s =>
    val task = IO[Int](throw DummyException("dummy")).onErrorRecoverWith { case _: DummyException =>
      IO.evalAsync(99).delayExecution(1.second)
    }

    val f = task.runToFuture
    assertEquals(f.value, None)
    // cancelling after scheduled for execution, but before execution
    s.tick(); assertEquals(f.value, None)

    f.cancel(); s.tick()
    assertEquals(f.value, None)
  }

  test("IO#onErrorRecover should emit error if not matches") { implicit s =>
    val dummy = DummyException("dummy")
    val task = IO[Int](throw dummy).onErrorRecover { case _: TimeoutException => 10 }
    val f = task.attempt.runToFuture; s.tick()
    assertEquals(f.value, Some(Success(Left(dummy))))
  }

  test("IO#onErrorRecoverWith should emit error if not matches") { implicit s =>
    val dummy = DummyException("dummy")
    val task = IO[Int](throw dummy).onErrorRecoverWith { case _: TimeoutException => Task.now(10) }
    val f = task.runToFuture; s.tick()
    assertEquals(f.value, Some(Failure(dummy)))
  }

  test("IO.eval.flatMap.redeemCauseWith should work") { implicit s =>
    val dummy = DummyException("dummy")
    val task = UIO.eval(1).flatMap(_ => throw dummy).redeemCauseWith(_ => IO.now(10), IO.now)

    val f = task.runToFuture
    assertEquals(f.value, Some(Success(10)))
  }

  test("IO.evalAsync.flatMap.redeemCauseWith should work") { implicit s =>
    val dummy = DummyException("dummy")
    val task = UIO.evalAsync(1).flatMap(_ => throw dummy).redeemCauseWith(_ => IO.now(10), IO.now)

    val f = task.runToFuture; s.tick()
    assertEquals(f.value, Some(Success(10)))
  }

  test("IO.now.onErrorRecoverWith should be stack safe") { implicit s =>
    val ex = 1111
    val count = if (Platform.isJVM) 50000 else 5000

    def loop(task: IO[Int, Int], n: Int): IO[Int, Int] =
      task.onErrorRecoverWith {
        case `ex` if n <= 0 => IO.now(count)
        case `ex` => loop(task, n - 1)
      }

    val task = loop(IO.raiseError(ex), count)
    val result = task.attempt.runToFuture

    s.tick()
    assertEquals(result.value, Some(Success(Right(count))))
  }

  test("onErrorRecoverWith should be stack safe for loop with executeAsync boundaries") { implicit s =>
    val ex = 2222
    val count = if (Platform.isJVM) 50000 else 5000

    def loop(task: IO[Int, Int], n: Int): IO[Int, Int] =
      task.onErrorRecoverWith {
        case `ex` if n <= 0 => UIO.evalAsync(count)
        case `ex` => loop(task, n - 1).executeAsync
      }

    val task = loop(IO.raiseError(ex), count)
    val result = task.attempt.runToFuture

    s.tick()
    assertEquals(result.value, Some(Success(Right(count))))
  }

  test("Task.onErrorRestartLoop works for success") { implicit s =>
    val dummy = DummyException("dummy1")
    var tries = 0
    val source = Task.eval {
      tries += 1
      if (tries < 5) throw dummy
      tries
    }

    val task = source.onErrorRestartLoop(10) { (err, maxRetries, retry) =>
      if (maxRetries > 0)
        retry(maxRetries - 1)
      else
        Task.raiseError(err)
    }

    val f = task.runToFuture
    assertEquals(f.value, Some(Success(5)))
    assertEquals(tries, 5)
  }

  test("Task.onErrorRestartLoop can throw different error") { implicit s =>
    val dummy = DummyException("dummy")
    val timeout = new TimeoutException("timeout")
    val source = Task.eval[Int] { throw dummy }

    val task = source.onErrorRestartLoop(5) { (_, maxRetries, retry) =>
      if (maxRetries > 0)
        retry(maxRetries - 1)
      else
        Task.raiseError(timeout)
    }

    val f = task.runToFuture
    assertEquals(f.value, Some(Failure(timeout)))
  }

  test("Task.onErrorRestartLoop can rethrow") { implicit s =>
    val dummy = DummyException("dummy")
    val source = Task.eval[Int] { throw dummy }

    val task = source.onErrorRestartLoop(10) { (err, maxRetries, retry) =>
      if (maxRetries > 0)
        retry(maxRetries - 1)
      else
        Task.raiseError(err)
    }

    val f = task.runToFuture
    assertEquals(f.value, Some(Failure(dummy)))
  }
}
